<?xml version="1.0" ?>
<!-- =================================================================================== -->
<!-- |    This document was autogenerated by xacro from diablo_ASM.xacro               | -->
<!-- |    EDITING THIS FILE BY HAND IS NOT RECOMMENDED                                 | -->
<!-- =================================================================================== -->
<robot name="diablo_ASM">
  <link name="diablo_base_link">
    <inertial>
      <origin rpy="0 0 0" xyz="0 0 0"/>
      <mass value="7"/>
      <inertia ixx="0.0417905" ixy="-3.4931e-09" ixz="-0.00056858" iyy="0.0942623" iyz="-9.55025e-09" izz="0.0855825"/>
    </inertial>
    <visual>
      <origin rpy="0 0 0" xyz="0 0 0"/>
      <geometry>
        <mesh filename="../meshes/base_link.stl" scale="0.1 0.1 0.1"/>
      </geometry>
    </visual>
    <collision>
      <origin rpy="0 0 0" xyz="0 0 0"/>
      <geometry>
        <mesh filename="../meshes/base_link.stl" scale="0.1 0.1 0.1"/>
      </geometry>
    </collision>
  </link>

  <link name="left_wheel">
    <inertial>
      <origin rpy="0 0 0" xyz="0 0 0"/>
      <mass value="2.9494"/>
      <inertia ixx="0.0069338" ixy="2.8693e-09" ixz="4.6779e-09" iyy="0.006934" iyz="-5.0441e-11" izz="0.012567"/>
    </inertial>
    <visual>
      <origin rpy="0 0 0" xyz="0 0 0"/>
      <geometry>
        <mesh filename="../meshes/left_wheel.STL" scale="1 1 1"/>
      </geometry>
    </visual>
    <collision>
      <origin rpy="0 0 0" xyz="0 0 0"/>
      <geometry>
        <mesh filename="../meshes/left_wheel.STL" scale="1 1 1"/>
      </geometry>
    </collision>
  </link>
  <link name="right_wheel">
    <inertial>
      <origin rpy="0 0 0" xyz="0 0 0"/>
      <mass value="2.9494"/>
      <inertia ixx="0.0069338" ixy="2.8693e-09" ixz="4.6779e-09" iyy="0.006934" iyz="-5.0441e-11" izz="0.012567"/>
    </inertial>
    <visual>
      <origin rpy="0 0 0" xyz="0 0 0"/>
      <geometry>
        <mesh filename="../meshes/right_wheel.STL" scale="1 1 1"/>
      </geometry>
    </visual>
    <collision>
      <origin rpy="0 0 0" xyz="0 0 0"/>
      <geometry>
        <mesh filename="../meshes/right_wheel.STL" scale="1 1 1"/>
      </geometry>
    </collision>
  </link>
  <link name="left_fake_thigh_link">
    <inertial>
      <origin rpy="0 0 0" xyz="0 0 0"/>
      <mass value="2.5"/>
      <inertia ixx="0.006704" ixy="5.557e-09" ixz="-0.000131826" iyy="0.0069816" iyz="9.009e-10" izz="0.0069712"/>
    </inertial>
    <visual>
      <origin rpy="0 0 0" xyz="0 0 0"/>
      <geometry>
        <mesh filename="../meshes/left_motor.STL" scale="1 1 1"/>
      </geometry>
    </visual>
    <collision>
      <origin rpy="0 0 0" xyz="0 0 0"/>
      <geometry>
        <mesh filename="../meshes/left_motor.STL" scale="1 1 1"/>
      </geometry>
    </collision>
  </link>
  <link name="right_fake_thigh_link">
    <inertial>
      <origin rpy="0 0 0" xyz="0 0 0"/>
      <mass value="2.5"/>
      <inertia ixx="0.006704" ixy="5.557e-09" ixz="-0.000131826" iyy="0.0069816" iyz="9.009e-10" izz="0.0069712"/>
    </inertial>
    <visual>
      <origin rpy="0 0 0" xyz="0 0 0"/>
      <geometry>
        <mesh filename="../meshes/right_motor.STL" scale="1 1 1"/>
      </geometry>
    </visual>
    <collision>
      <origin rpy="0 0 0" xyz="0 0 0"/>
      <geometry>
        <mesh filename="../meshes/right_motor.STL" scale="1 1 1"/>
      </geometry>
    </collision>
  </link>
  <link name="left_fake_shank_link">
    <inertial>
      <origin rpy="0 0 0" xyz="0 0 0"/>
      <mass value="0.071103"/>
      <inertia ixx="1.6657e-05" ixy="-5.5246e-06" ixz="3.9598e-14" iyy="0.00017966" iyz="-6.5493e-15" izz="0.00019328"/>
    </inertial>
    <visual>
      <origin rpy="0 0 0" xyz="0 0 0"/>
      <geometry>
        <mesh filename="../meshes/left_leg3.STL" scale="1 1 1"/>
      </geometry>
    </visual>
    <collision>
      <origin rpy="0 0 0" xyz="0 0 0"/>
      <geometry>
        <mesh filename="../meshes/left_leg3.STL" scale="1 1 1"/>
      </geometry>
    </collision>
  </link>
  <link name="right_fake_shank_link">
    <inertial>
      <origin rpy="0 0 0" xyz="0 0 0"/>
      <mass value="0.071103"/>
      <inertia ixx="1.6657e-05" ixy="-5.5246e-06" ixz="1.4852e-14" iyy="0.00017966" iyz="-6.5194e-14" izz="0.00019328"/>
    </inertial>
    <visual>
      <origin rpy="0 0 0" xyz="0 0 0"/>
      <geometry>
        <mesh filename="../meshes/right_leg3.STL" scale="1 1 1"/>
      </geometry>
    </visual>
    <collision>
      <origin rpy="0 0 0" xyz="0 0 0"/>
      <geometry>
        <mesh filename="../meshes/right_leg3.STL" scale="1 1 1"/>
      </geometry>
    </collision>
  </link>
  <joint name="left_fake_hip_joint" type="revolute">
    <origin rpy="1.5708 0.13433 -3.1416" xyz="0 0.18755 0"/>
    <parent link="diablo_base_link"/>
    <child link="left_fake_thigh_link"/>
    <axis xyz="0 0 1"/>
    <limit effort="27" lower="-1.57" upper="1.57" velocity="26"/>
  </joint>
  <joint name="left_fake_knee_joint" type="revolute">
    <origin rpy="0 0 -2.8729" xyz="0.14 0 0"/>
    <parent link="left_fake_thigh_link"/>
    <child link="left_fake_shank_link"/>
    <axis xyz="0 0 1"/>
    <limit effort="27" lower="-1.57" upper="1.57" velocity="26"/>
  </joint>
  <joint name="right_fake_hip_joint" type="revolute">
    <origin rpy="1.5708 0.13433 3.1416" xyz="0 -0.18755 0"/>
    <parent link="diablo_base_link"/>
    <child link="right_fake_thigh_link"/>
    <axis xyz="0 0 1"/>
    <limit effort="27" lower="-1.57" upper="1.57" velocity="26"/>
  </joint>
  <joint name="right_fake_knee_joint" type="revolute">
    <origin rpy="0 0 -2.8729" xyz="0.14 0 0"/>
    <parent link="right_fake_thigh_link"/>
    <child link="right_fake_shank_link"/>
    <axis xyz="0 0 1"/>
    <limit effort="27" lower="-1.57" upper="1.57" velocity="26"/>
  </joint>
  <joint name="left_wheel_joint" type="revolute">
    <origin rpy="0 0 0.13433" xyz="0.14 0 0.025"/>
    <parent link="left_fake_shank_link"/>
    <child link="left_wheel"/>
    <axis xyz="0 0 1"/>
    <limit effort="5" velocity="26" />
  </joint>
  <joint name="right_wheel_joint" type="revolute">
    <origin rpy="0 0 0.13433" xyz="0.14 0 -0.025"/>
    <parent link="right_fake_shank_link"/>
    <child link="right_wheel"/>
    <axis xyz="0 0 1"/>
    <limit effort="5" velocity="26" />
  </joint>
</robot>
