<?xml version="1.0" ?>
<!-- =================================================================================== -->
<!-- |    This document was autogenerated by xacro from diablo.xacro                   | -->
<!-- |    EDITING THIS FILE BY HAND IS NOT RECOMMENDED                                 | -->
<!-- =================================================================================== -->
<robot name="robot">
  <link name="diablo_base_link">
    <inertial>
      <origin rpy="0 0 0" xyz="0 0 0"/>
      <mass value="11.639"/>
      <inertia ixx="0.071628" ixy="-5.9879e-09" ixz="-0.00097471" iyy="0.16274" iyz="-1.6369e-08" izz="0.14673"/>
    </inertial>
    <visual>
      <origin rpy="0 0 0" xyz="0 0 0"/>
      <geometry>
        <mesh filename="package://diablo/description/meshes/base_link.stl" scale="0.1 0.1 0.1"/>
      </geometry>
    </visual>
    <collision>
      <origin rpy="0 0 0" xyz="0 0 0"/>
      <geometry>
        <mesh filename="package://diablo/description/meshes/base_link.stl" scale="0.1 0.001 0.1"/>
      </geometry>
    </collision>
  </link>
  <link name="left_thigh_link">
    <inertial>
      <origin rpy="0 0 0" xyz="0 0 0"/>
      <mass value="0.10382"/>
      <inertia ixx="3.6972e-05" ixy="2.4106e-05" ixz="4.3699e-10" iyy="0.00029278" iyz="-4.1243e-11" izz="0.00032532"/>
    </inertial>
    <visual>
      <origin rpy="0 0 0" xyz="0 0 0"/>
      <geometry>
        <mesh filename="package://diablo/description/meshes/left_leg1.STL" scale="1 1 1"/>
      </geometry>
    </visual>
    <collision>
      <origin rpy="0 0 0" xyz="0 0 0"/>
      <geometry>
        <mesh filename="package://diablo/description/meshes/left_leg1.STL" scale="1 1 1"/>
      </geometry>
    </collision>
  </link>
  <link name="left_shank_link">
    <inertial>
      <origin rpy="0 0 0" xyz="0 0 0"/>
      <mass value="0.18218"/>
      <inertia ixx="4.1372e-05" ixy="5.1445e-09" ixz="-7.3659e-06" iyy="0.00048219" iyz="2.5521e-11" izz="0.00050441"/>
    </inertial>
    <visual>
      <origin rpy="0 0 0" xyz="0 0 0"/>
      <geometry>
        <mesh filename="package://diablo/description/meshes/left_leg2.STL" scale="1 1 1"/>
      </geometry>
    </visual>
    <collision>
      <origin rpy="0 0 0" xyz="0 0 0"/>
      <geometry>
        <mesh filename="package://diablo/description/meshes/left_leg2.STL" scale="1 1 1"/>
      </geometry>
    </collision>
  </link>
  <link name="left_wheel">
    <inertial>
      <origin rpy="0 0 0" xyz="0 0 0"/>
      <mass value="2.9494"/>
      <inertia ixx="0.0069338" ixy="2.8693e-09" ixz="4.6779e-09" iyy="0.006934" iyz="-5.0441e-11" izz="0.012567"/>
    </inertial>
    <visual>
      <origin rpy="0 0 0" xyz="0 0 0"/>
      <geometry>
        <mesh filename="package://diablo/description/meshes/left_wheel.STL" scale="1 1 1"/>
      </geometry>
    </visual>
    <collision>
      <origin rpy="0 0 0" xyz="0 0 0"/>
      <geometry>
        <mesh filename="package://diablo/description/meshes/left_wheel.STL" scale="1 1 1"/>
      </geometry>
    </collision>
  </link>
  <link name="right_thigh_link">
    <inertial>
      <origin rpy="0 0 0" xyz="0 0 0"/>
      <mass value="0.10382"/>
      <inertia ixx="3.6972e-05" ixy="2.4106e-05" ixz="-4.3686e-10" iyy="0.00029278" iyz="4.1459e-11" izz="0.00032532"/>
    </inertial>
    <visual>
      <origin rpy="0 0 0" xyz="0 0 0"/>
      <geometry>
        <mesh filename="package://diablo/description/meshes/right_leg1.STL" scale="1 1 1"/>
      </geometry>
    </visual>
    <collision>
      <origin rpy="0 0 0" xyz="0 0 0"/>
      <geometry>
        <mesh filename="package://diablo/description/meshes/right_leg1.STL" scale="1 1 1"/>
      </geometry>
    </collision>
  </link>
  <link name="right_shank_link">
    <inertial>
      <origin rpy="0 0 0" xyz="0 0 0"/>
      <mass value="0.18218"/>
      <inertia ixx="4.1372e-05" ixy="5.1777e-09" ixz="7.3659e-06" iyy="0.00048219" iyz="4.5225e-11" izz="0.00050441"/>
    </inertial>
    <visual>
      <origin rpy="0 0 0" xyz="0 0 0"/>
      <geometry>
        <mesh filename="package://diablo/description/meshes/right_leg2.STL" scale="1 1 1"/>
      </geometry>
    </visual>
    <collision>
      <origin rpy="0 0 0" xyz="0 0 0"/>
      <geometry>
        <mesh filename="package://diablo/description/meshes/right_leg2.STL" scale="1 1 1"/>
      </geometry>
    </collision>
  </link>
  <link name="right_wheel">
    <inertial>
      <origin rpy="0 0 0" xyz="0 0 0"/>
      <mass value="2.9494"/>
      <inertia ixx="0.0069339" ixy="-1.3146e-07" ixz="-3.0392e-09" iyy="0.0069339" iyz="-3.5756e-09" izz="0.012567"/>
    </inertial>
    <visual>
      <origin rpy="0 0 0" xyz="0 0 0"/>
      <geometry>
        <mesh filename="package://diablo/description/meshes/right_wheel.STL" scale="1 1 1"/>
      </geometry>
    </visual>
    <collision>
      <origin rpy="0 0 0" xyz="0 0 0"/>
      <geometry>
        <mesh filename="package://diablo/description/meshes/right_wheel.STL" scale="1 1 1"/>
      </geometry>
    </collision>
  </link>
  <link name="left_fake_thigh_link">
    <inertial>
      <origin rpy="0 0 0" xyz="0 0 0"/>
      <mass value="1.3837"/>
      <inertia ixx="0.003352" ixy="2.7785e-09" ixz="-6.5913e-05" iyy="0.0034908" iyz="4.5045e-10" izz="0.0034856"/>
    </inertial>
    <visual>
      <origin rpy="0 0 0" xyz="0 0 0"/>
      <geometry>
        <mesh filename="package://diablo/description/meshes/left_motor.STL" scale="1 1 1"/>
      </geometry>
    </visual>
    <collision>
      <origin rpy="0 0 0" xyz="0 0 0"/>
      <geometry>
        <mesh filename="package://diablo/description/meshes/left_motor.STL" scale="1 1 1"/>
      </geometry>
    </collision>
  </link>
  <link name="right_fake_thigh_link">
    <inertial>
      <origin rpy="0 0 0" xyz="0 0 0"/>
      <mass value="1.3838"/>
      <inertia ixx="0.003352" ixy="-2.6527e-09" ixz="6.5914e-05" iyy="0.0034908" iyz="-7.2968e-10" izz="0.0034856"/>
    </inertial>
    <visual>
      <origin rpy="0 0 0" xyz="0 0 0"/>
      <geometry>
        <mesh filename="package://diablo/description/meshes/right_motor.STL" scale="1 1 1"/>
      </geometry>
    </visual>
    <collision>
      <origin rpy="0 0 0" xyz="0 0 0"/>
      <geometry>
        <mesh filename="package://diablo/description/meshes/right_motor.STL" scale="1 1 1"/>
      </geometry>
    </collision>
  </link>
  <!-- Imu is fixed to the base link -->
  <joint name="base_imu_joint" type="fixed">
    <origin rpy="0.00 0.00 0.00" xyz="0.00 0.00 0.00"/>
    <parent link="diablo_base_link"/>
    <child link="base_imu"/>
  </joint>
  <!-- Imu link -->
  <link name="base_imu">
    <inertial>
      <mass value="0.01"/>
      <origin rpy="0 0 0" xyz="0 0 0"/>
      <inertia ixx="0.000001" ixy="0" ixz="0" iyy="0.000001" iyz="0" izz="0.000001"/>
    </inertial>
    <visual>
      <origin rpy="0 0 0" xyz="0 0 0"/>
      <geometry>
        <mesh filename="package://diablo/urdf/imu/imu.stl" scale="1 1 1"/>
      </geometry>
    </visual>
    <material name="orange">
      <color rgba="255 108 10 255"/>
    </material>
  </link>
  <gazebo reference="base_imu">
    <material>Gazebo/Orange</material>
  </gazebo>
  <gazebo reference="base_imu_joint">
    <disableFixedJointLumping>true</disableFixedJointLumping>
  </gazebo>
  <transmission name="right_hip_joint_tran">
    <type>transmission_interface/SimpleTransmission</type>
    <joint name="right_hip_joint">
      <hardwareInterface>hardware_interface/EffortJointInterface</hardwareInterface>
    </joint>
    <actuator name="right_hip_joint_motor">
      <hardwareInterface>hardware_interface/EffortJointInterface</hardwareInterface>
      <mechanicalReduction>1</mechanicalReduction>
    </actuator>
  </transmission>
  <transmission name="right_knee_joint_tran">
    <type>transmission_interface/SimpleTransmission</type>
    <joint name="right_knee_joint">
      <hardwareInterface>hardware_interface/EffortJointInterface</hardwareInterface>
    </joint>
    <actuator name="right_knee_joint_motor">
      <hardwareInterface>hardware_interface/EffortJointInterface</hardwareInterface>
      <mechanicalReduction>1</mechanicalReduction>
    </actuator>
  </transmission>
  <transmission name="left_hip_joint_tran">
    <type>transmission_interface/SimpleTransmission</type>
    <joint name="left_hip_joint">
      <hardwareInterface>hardware_interface/EffortJointInterface</hardwareInterface>
    </joint>
    <actuator name="left_hip_joint_motor">
      <hardwareInterface>hardware_interface/EffortJointInterface</hardwareInterface>
      <mechanicalReduction>1</mechanicalReduction>
    </actuator>
  </transmission>
  <transmission name="left_knee_joint_tran">
    <type>transmission_interface/SimpleTransmission</type>
    <joint name="left_knee_joint">
      <hardwareInterface>hardware_interface/EffortJointInterface</hardwareInterface>
    </joint>
    <actuator name="left_knee_joint_motor">
      <hardwareInterface>hardware_interface/EffortJointInterface</hardwareInterface>
      <mechanicalReduction>1</mechanicalReduction>
    </actuator>
  </transmission>
  <transmission name="left_wheel_joint_tran">
    <type>transmission_interface/SimpleTransmission</type>
    <joint name="left_wheel_joint">
      <hardwareInterface>hardware_interface/EffortJointInterface</hardwareInterface>
    </joint>
    <actuator name="left_wheel_joint_motor">
      <hardwareInterface>hardware_interface/EffortJointInterface</hardwareInterface>
      <mechanicalReduction>1</mechanicalReduction>
    </actuator>
  </transmission>
  <transmission name="right_wheel_joint_tran">
    <type>transmission_interface/SimpleTransmission</type>
    <joint name="right_wheel_joint">
      <hardwareInterface>hardware_interface/EffortJointInterface</hardwareInterface>
    </joint>
    <actuator name="right_wheel_joint_motor">
      <hardwareInterface>hardware_interface/EffortJointInterface</hardwareInterface>
      <mechanicalReduction>1</mechanicalReduction>
    </actuator>
  </transmission>
  <!--            <xacro:create_transmission joint_name="left_wheel_joint" hardware_interface="VelocityJointInterface"/>-->
  <!--            <xacro:create_transmission joint_name="right_wheel_joint" hardware_interface="VelocityJointInterface"/>-->
  <joint name="left_hip_joint" type="revolute">
    <origin rpy="0 0 -2.8729" xyz="0 0 0"/>
    <parent link="left_fake_thigh_link"/>
    <child link="left_thigh_link"/>
    <axis xyz="0 0 1"/>
    <limit effort="27" lower="-3.14" upper="3.14" velocity="26"/>
  </joint>
  <joint name="left_knee_joint" type="revolute">
    <origin rpy="0 0 2.8729" xyz="0.14 0 0"/>
    <parent link="left_thigh_link"/>
    <child link="left_shank_link"/>
    <axis xyz="0 0 1"/>
    <limit effort="27" lower="-3.14" upper="3.14" velocity="26"/>
  </joint>
  <joint name="right_hip_joint" type="revolute">
    <origin rpy="0 0 -2.8729" xyz="0 0 0"/>
    <parent link="right_fake_thigh_link"/>
    <child link="right_thigh_link"/>
    <axis xyz="0 0 1"/>
    <limit effort="27" lower="-3.14" upper="3.14" velocity="26"/>
  </joint>
  <joint name="right_knee_joint" type="revolute">
    <origin rpy="0 0 2.8729" xyz="0.14 0 0"/>
    <parent link="right_thigh_link"/>
    <child link="right_shank_link"/>
    <axis xyz="0 0 1"/>
    <limit effort="27" lower="-3.14" upper="3.14" velocity="26"/>
  </joint>
  <joint name="left_fake_hip_joint" type="fixed">
    <origin rpy="1.5708 0.13433 -3.1416" xyz="0 0.18755 0"/>
    <parent link="diablo_base_link"/>
    <child link="left_fake_thigh_link"/>
  </joint>
  <joint name="right_fake_hip_joint" type="fixed">
    <origin rpy="1.5708 0.13433 3.1416" xyz="0 -0.18755 0"/>
    <parent link="diablo_base_link"/>
    <child link="right_fake_thigh_link"/>
  </joint>
  <joint name="left_wheel_joint" type="continuous">
    <origin rpy="0 0 0.13433" xyz="0.14 0 0.0537"/>
    <parent link="left_shank_link"/>
    <child link="left_wheel"/>
    <axis xyz="0 0 1"/>
    <limit effort="27" velocity="26"/>
  </joint>
  <joint name="right_wheel_joint" type="continuous">
    <origin rpy="0 0 -3.0073" xyz="0.14 0 -0.0537"/>
    <parent link="right_shank_link"/>
    <child link="right_wheel"/>
    <axis xyz="0 0 1"/>
    <limit effort="27" velocity="26"/>
  </joint>
  <gazebo>
    <plugin filename="librobot_hw_sim.so" name="robot_ros_control">
      <robotNamespace>/</robotNamespace>
      <robotSimType>robot_gazebo/RobotHWSim</robotSimType>
    </plugin>
  </gazebo>
</robot>
